[2023-09-03T08:32:55.524+0000] {logging_mixin.py:151} INFO - Changing /opt/***/logs/dag_id=Autotrader_ETL_DAG/run_id=manual__2023-09-03T08:31:22.720588+00:00/task_id=create_listing_fact permission to 509
[2023-09-03T08:32:55.525+0000] {logging_mixin.py:151} INFO - Failed to change /opt/***/logs/dag_id=Autotrader_ETL_DAG/run_id=manual__2023-09-03T08:31:22.720588+00:00/task_id=create_listing_fact permission to 509: [Errno 1] Operation not permitted: '/opt/***/logs/dag_id=Autotrader_ETL_DAG/run_id=manual__2023-09-03T08:31:22.720588+00:00/task_id=create_listing_fact'
[2023-09-03T08:32:55.555+0000] {logging_mixin.py:151} INFO - Changing /opt/***/logs/dag_id=Autotrader_ETL_DAG/run_id=manual__2023-09-03T08:31:22.720588+00:00/task_id=create_listing_fact permission to 509
[2023-09-03T08:32:55.557+0000] {logging_mixin.py:151} INFO - Failed to change /opt/***/logs/dag_id=Autotrader_ETL_DAG/run_id=manual__2023-09-03T08:31:22.720588+00:00/task_id=create_listing_fact permission to 509: [Errno 1] Operation not permitted: '/opt/***/logs/dag_id=Autotrader_ETL_DAG/run_id=manual__2023-09-03T08:31:22.720588+00:00/task_id=create_listing_fact'
[2023-09-03T08:32:55.584+0000] {taskinstance.py:1159} INFO - Dependencies all met for dep_context=non-requeueable deps ti=<TaskInstance: Autotrader_ETL_DAG.create_listing_fact manual__2023-09-03T08:31:22.720588+00:00 [queued]>
[2023-09-03T08:32:55.594+0000] {taskinstance.py:1159} INFO - Dependencies all met for dep_context=requeueable deps ti=<TaskInstance: Autotrader_ETL_DAG.create_listing_fact manual__2023-09-03T08:31:22.720588+00:00 [queued]>
[2023-09-03T08:32:55.595+0000] {taskinstance.py:1361} INFO - Starting attempt 2 of 2
[2023-09-03T08:32:55.608+0000] {taskinstance.py:1382} INFO - Executing <Task(BigQueryExecuteQueryOperator): create_listing_fact> on 2023-09-03 08:31:22.720588+00:00
[2023-09-03T08:32:55.613+0000] {standard_task_runner.py:57} INFO - Started process 3288 to run task
[2023-09-03T08:32:55.616+0000] {standard_task_runner.py:84} INFO - Running: ['***', 'tasks', 'run', 'Autotrader_ETL_DAG', 'create_listing_fact', 'manual__2023-09-03T08:31:22.720588+00:00', '--job-id', '164', '--raw', '--subdir', 'DAGS_FOLDER/autotrader_etl.py', '--cfg-path', '/tmp/tmpj89bxqxd']
[2023-09-03T08:32:55.618+0000] {standard_task_runner.py:85} INFO - Job 164: Subtask create_listing_fact
[2023-09-03T08:32:55.666+0000] {logging_mixin.py:151} INFO - Changing /opt/***/logs/dag_id=Autotrader_ETL_DAG/run_id=manual__2023-09-03T08:31:22.720588+00:00/task_id=create_listing_fact permission to 509
[2023-09-03T08:32:55.667+0000] {logging_mixin.py:151} INFO - Failed to change /opt/***/logs/dag_id=Autotrader_ETL_DAG/run_id=manual__2023-09-03T08:31:22.720588+00:00/task_id=create_listing_fact permission to 509: [Errno 1] Operation not permitted: '/opt/***/logs/dag_id=Autotrader_ETL_DAG/run_id=manual__2023-09-03T08:31:22.720588+00:00/task_id=create_listing_fact'
[2023-09-03T08:32:55.669+0000] {task_command.py:415} INFO - Running <TaskInstance: Autotrader_ETL_DAG.create_listing_fact manual__2023-09-03T08:31:22.720588+00:00 [running]> on host 1a0e8b05e04d
[2023-09-03T08:32:55.754+0000] {taskinstance.py:1660} INFO - Exporting env vars: AIRFLOW_CTX_DAG_OWNER='***' AIRFLOW_CTX_DAG_ID='Autotrader_ETL_DAG' AIRFLOW_CTX_TASK_ID='create_listing_fact' AIRFLOW_CTX_EXECUTION_DATE='2023-09-03T08:31:22.720588+00:00' AIRFLOW_CTX_TRY_NUMBER='2' AIRFLOW_CTX_DAG_RUN_ID='manual__2023-09-03T08:31:22.720588+00:00'
[2023-09-03T08:32:55.756+0000] {bigquery.py:1234} INFO - Executing: CREATE TABLE IF NOT EXISTS
        autotrader-toyota-dashboard.autotrader_transformed.listing_fact 
        (
        car_key INT64 NOT NULL,
        location_key INT64 NOT NULL,
        odometer INT64 NOT NULL,
        price INT64 NOT NULL
        PRIMARY KEY (car_key,location_key) NOT ENFORCED
        FOREIGN KEY (car_key) REFERENCES autotrader-toyota-dashboard.autotrader_transformed.car_dim(car_key) NOT ENFORCED
        FOREIGN KEY (location_key) REFERENCES autotrader-toyota-dashboard.autotrader_transformed.location_dim(location_key) NOT ENFORCED
        );
[2023-09-03T08:32:55.767+0000] {connection.py:232} WARNING - Connection schemes (type: google_cloud_platform) shall not contain '_' according to RFC3986.
[2023-09-03T08:32:55.772+0000] {base.py:73} INFO - Using connection ID 'google_cloud' for task execution.
[2023-09-03T08:32:55.778+0000] {logging_mixin.py:151} WARNING - /home/***/.local/lib/python3.8/site-packages/***/providers/google/cloud/hooks/bigquery.py:2109 AirflowProviderDeprecationWarning: This method is deprecated. Please use `BigQueryHook.insert_job` method.
[2023-09-03T08:32:55.824+0000] {bigquery.py:1596} INFO - Inserting job ***_1693729975824360_38709eb8741eeb8269710481fecacfbc
[2023-09-03T08:32:57.351+0000] {taskinstance.py:1943} ERROR - Task failed with exception
Traceback (most recent call last):
  File "/home/airflow/.local/lib/python3.8/site-packages/airflow/providers/google/cloud/operators/bigquery.py", line 1242, in execute
    self.job_id = self.hook.run_query(
  File "/home/airflow/.local/lib/python3.8/site-packages/airflow/providers/google/cloud/hooks/bigquery.py", line 2244, in run_query
    job = self.insert_job(configuration=configuration, project_id=self.project_id, location=location)
  File "/home/airflow/.local/lib/python3.8/site-packages/airflow/providers/google/common/hooks/base_google.py", line 467, in inner_wrapper
    return func(self, *args, **kwargs)
  File "/home/airflow/.local/lib/python3.8/site-packages/airflow/providers/google/cloud/hooks/bigquery.py", line 1602, in insert_job
    job_api_repr.result(timeout=timeout, retry=retry)
  File "/home/airflow/.local/lib/python3.8/site-packages/google/cloud/bigquery/job/query.py", line 1520, in result
    do_get_result()
  File "/home/airflow/.local/lib/python3.8/site-packages/google/cloud/bigquery/job/query.py", line 1510, in do_get_result
    super(QueryJob, self).result(retry=retry, timeout=timeout)
  File "/home/airflow/.local/lib/python3.8/site-packages/google/cloud/bigquery/job/base.py", line 922, in result
    return super(_AsyncJob, self).result(timeout=timeout, **kwargs)
  File "/home/airflow/.local/lib/python3.8/site-packages/google/api_core/future/polling.py", line 261, in result
    raise self._exception
google.api_core.exceptions.BadRequest: 400 Syntax error: Expected ")" or "," but got "(" at [8:21]

Location: US
Job ID: airflow_1693729975824360_38709eb8741eeb8269710481fecacfbc

[2023-09-03T08:32:57.363+0000] {taskinstance.py:1400} INFO - Marking task as FAILED. dag_id=Autotrader_ETL_DAG, task_id=create_listing_fact, execution_date=20230903T083122, start_date=20230903T083255, end_date=20230903T083257
[2023-09-03T08:32:57.377+0000] {standard_task_runner.py:104} ERROR - Failed to execute job 164 for task create_listing_fact (400 Syntax error: Expected ")" or "," but got "(" at [8:21]

Location: US
Job ID: airflow_1693729975824360_38709eb8741eeb8269710481fecacfbc
; 3288)
[2023-09-03T08:32:57.395+0000] {local_task_job_runner.py:228} INFO - Task exited with return code 1
[2023-09-03T08:32:57.422+0000] {taskinstance.py:2784} INFO - 0 downstream tasks scheduled from follow-on schedule check
