[2023-08-31T08:50:31.557+0000] {logging_mixin.py:151} INFO - Changing /opt/***/logs/dag_id=Autotrader_ETL_DAG/run_id=manual__2023-08-31T08:49:44.297192+00:00/task_id=create_listings_raw_table permission to 509
[2023-08-31T08:50:31.558+0000] {logging_mixin.py:151} INFO - Failed to change /opt/***/logs/dag_id=Autotrader_ETL_DAG/run_id=manual__2023-08-31T08:49:44.297192+00:00/task_id=create_listings_raw_table permission to 509: [Errno 1] Operation not permitted: '/opt/***/logs/dag_id=Autotrader_ETL_DAG/run_id=manual__2023-08-31T08:49:44.297192+00:00/task_id=create_listings_raw_table'
[2023-08-31T08:50:31.584+0000] {logging_mixin.py:151} INFO - Changing /opt/***/logs/dag_id=Autotrader_ETL_DAG/run_id=manual__2023-08-31T08:49:44.297192+00:00/task_id=create_listings_raw_table permission to 509
[2023-08-31T08:50:31.585+0000] {logging_mixin.py:151} INFO - Failed to change /opt/***/logs/dag_id=Autotrader_ETL_DAG/run_id=manual__2023-08-31T08:49:44.297192+00:00/task_id=create_listings_raw_table permission to 509: [Errno 1] Operation not permitted: '/opt/***/logs/dag_id=Autotrader_ETL_DAG/run_id=manual__2023-08-31T08:49:44.297192+00:00/task_id=create_listings_raw_table'
[2023-08-31T08:50:31.605+0000] {taskinstance.py:1159} INFO - Dependencies all met for dep_context=non-requeueable deps ti=<TaskInstance: Autotrader_ETL_DAG.create_listings_raw_table manual__2023-08-31T08:49:44.297192+00:00 [queued]>
[2023-08-31T08:50:31.612+0000] {taskinstance.py:1159} INFO - Dependencies all met for dep_context=requeueable deps ti=<TaskInstance: Autotrader_ETL_DAG.create_listings_raw_table manual__2023-08-31T08:49:44.297192+00:00 [queued]>
[2023-08-31T08:50:31.612+0000] {taskinstance.py:1361} INFO - Starting attempt 2 of 2
[2023-08-31T08:50:31.624+0000] {taskinstance.py:1382} INFO - Executing <Task(BigQueryCreateEmptyTableOperator): create_listings_raw_table> on 2023-08-31 08:49:44.297192+00:00
[2023-08-31T08:50:31.630+0000] {standard_task_runner.py:57} INFO - Started process 3230 to run task
[2023-08-31T08:50:31.632+0000] {standard_task_runner.py:84} INFO - Running: ['***', 'tasks', 'run', 'Autotrader_ETL_DAG', 'create_listings_raw_table', 'manual__2023-08-31T08:49:44.297192+00:00', '--job-id', '108', '--raw', '--subdir', 'DAGS_FOLDER/autotrader_etl.py', '--cfg-path', '/tmp/tmpdomih7ba']
[2023-08-31T08:50:31.634+0000] {standard_task_runner.py:85} INFO - Job 108: Subtask create_listings_raw_table
[2023-08-31T08:50:31.673+0000] {logging_mixin.py:151} INFO - Changing /opt/***/logs/dag_id=Autotrader_ETL_DAG/run_id=manual__2023-08-31T08:49:44.297192+00:00/task_id=create_listings_raw_table permission to 509
[2023-08-31T08:50:31.674+0000] {logging_mixin.py:151} INFO - Failed to change /opt/***/logs/dag_id=Autotrader_ETL_DAG/run_id=manual__2023-08-31T08:49:44.297192+00:00/task_id=create_listings_raw_table permission to 509: [Errno 1] Operation not permitted: '/opt/***/logs/dag_id=Autotrader_ETL_DAG/run_id=manual__2023-08-31T08:49:44.297192+00:00/task_id=create_listings_raw_table'
[2023-08-31T08:50:31.677+0000] {task_command.py:415} INFO - Running <TaskInstance: Autotrader_ETL_DAG.create_listings_raw_table manual__2023-08-31T08:49:44.297192+00:00 [running]> on host 1a0e8b05e04d
[2023-08-31T08:50:31.747+0000] {taskinstance.py:1660} INFO - Exporting env vars: AIRFLOW_CTX_DAG_OWNER='***' AIRFLOW_CTX_DAG_ID='Autotrader_ETL_DAG' AIRFLOW_CTX_TASK_ID='create_listings_raw_table' AIRFLOW_CTX_EXECUTION_DATE='2023-08-31T08:49:44.297192+00:00' AIRFLOW_CTX_TRY_NUMBER='2' AIRFLOW_CTX_DAG_RUN_ID='manual__2023-08-31T08:49:44.297192+00:00'
[2023-08-31T08:50:31.763+0000] {taskinstance.py:1943} ERROR - Task failed with exception
Traceback (most recent call last):
  File "/home/airflow/.local/lib/python3.8/site-packages/airflow/providers/google/cloud/operators/bigquery.py", line 1489, in execute
    bq_hook = BigQueryHook(
  File "/home/airflow/.local/lib/python3.8/site-packages/airflow/providers/google/cloud/hooks/bigquery.py", line 116, in __init__
    super().__init__(
  File "/home/airflow/.local/lib/python3.8/site-packages/airflow/providers/google/common/hooks/base_google.py", line 237, in __init__
    self.extras: dict = self.get_connection(self.gcp_conn_id).extra_dejson
  File "/home/airflow/.local/lib/python3.8/site-packages/airflow/hooks/base.py", line 72, in get_connection
    conn = Connection.get_connection_from_secrets(conn_id)
  File "/home/airflow/.local/lib/python3.8/site-packages/airflow/models/connection.py", line 477, in get_connection_from_secrets
    raise AirflowNotFoundException(f"The conn_id `{conn_id}` isn't defined")
airflow.exceptions.AirflowNotFoundException: The conn_id `google_cloud_default` isn't defined
[2023-08-31T08:50:31.766+0000] {taskinstance.py:1400} INFO - Marking task as FAILED. dag_id=Autotrader_ETL_DAG, task_id=create_listings_raw_table, execution_date=20230831T084944, start_date=20230831T085031, end_date=20230831T085031
[2023-08-31T08:50:31.776+0000] {standard_task_runner.py:104} ERROR - Failed to execute job 108 for task create_listings_raw_table (The conn_id `google_cloud_default` isn't defined; 3230)
[2023-08-31T08:50:31.806+0000] {local_task_job_runner.py:228} INFO - Task exited with return code 1
[2023-08-31T08:50:31.830+0000] {taskinstance.py:2784} INFO - 0 downstream tasks scheduled from follow-on schedule check
